Workbook

Sheet Project Guide
A1: PR. Final Project — "Data Intelligence Dashboard"
A3: Purpose | B3: Analyze customer transactions and communicate business insights with Excel formulas, charts and a dashboard.
A4: Dataset | B4: A sample dataset of 250 customer transactions is included on the Raw Data sheet. Replace it with your instructor's dataset if provided.
A5: Workbook map | B5: Raw Data = source transactions | Analysis = formula-based summaries | Visualizations = charts | Dashboard = KPIs and visuals | What-If Analysis = scenarios and Goal Seek setup | Regression = linear trend model | Lists & Matching = repeated values, matching names and abbreviations | Final Report = insights.
A6: Key functions | B6: TODAY, NOW, DATEDIF, EOMONTH, FILTER, COUNTIF, SUMIF, SUMIFS, AVERAGEIF, IF, TEXT, LEFT, XLOOKUP/COUNTIF-style matching.
A7: Timestamp note | B7: The Timestamp column uses NOW() as a live formula example. Enable iterative calculation in Excel if you want to test a fixed timestamp workflow; otherwise it updates when recalculated.
A8: FILTER note | B8: FILTER is supported in Microsoft 365 / Excel 2021+. If your Excel version does not support FILTER, use the helper formula noted in Analysis.
A9: Pivot Tables | B9: The workbook includes formula-driven summaries and dashboard charts. To create native PivotTables/Slicers/Timelines, select the Raw Data table in Excel and use Insert > PivotTable, then Insert Slicer/Timeline.
A10: Regression | B10: The Regression sheet provides a transparent slope/intercept calculation using SLOPE and INTERCEPT. The Data Analysis ToolPak can be used to validate the model.
A11: How to use | B11: Start at Dashboard, inspect the Analysis sheet formulas, and read Final Report. Formulas are included in cells for review and editing.

Sheet Raw Data
A1: Transaction ID | B1: Transaction Date | C1: Customer ID | D1: Customer Name | E1: Region | F1: Product | G1: Category | H1: Quantity | I1: Unit Price (₹) | J1: Revenue (₹) | K1: Payment Method | L1: Sales Channel | M1: Month | N1: Customer Tenure (Days) | O1: Timestamp (NOW)
A2: T0001 | B2: 45772 | C2: C001 | D2: Aarav Patel | E2: North | F2: Premium Pen | G2: Stationery | H2: 1 | I2: 399 | J2: =H2*I2 | K2: UPI | L2: Mobile App | M2: =TEXT(B2,"mmm-yyyy") | N2: =DATEDIF(B2,TODAY(),"d") | O2: =NOW()
A3: T0002 | B3: 46216 | C3: C003 | D3: Vivaan Mehta | E3: West | F3: Headphones | G3: Electronics | H3: 2 | I3: 2499 | J3: =H3*I3 | K3: UPI | L3: Online | M3: =TEXT(B3,"mmm-yyyy") | N3: =DATEDIF(B3,TODAY(),"d") | O3: =NOW()
A4: T0003 | B4: 45896 | C4: C017 | D4: Kabir Mehta | E4: North | F4: Headphones | G4: Electronics | H4: 1 | I4: 2499 | J4: =H4*I4 | K4: Net Banking | L4: Store | M4: =TEXT(B4,"mmm-yyyy") | N4: =DATEDIF(B4,TODAY(),"d") | O4: =NOW()
A5: T0004 | B5: 45883 | C5: C015 | D5: Dev Shah | E5: West | F5: Headphones | G5: Electronics | H5: 1 | I5: 2499 | J5: =H5*I5 | K5: Credit Card | L5: Mobile App | M5: =TEXT(B5,"mmm-yyyy") | N5: =DATEDIF(B5,TODAY(),"d") | O5: =NOW()
A6: T0005 | B6: 46090 | C6: C011 | D6: Krish Dave | E6: South | F6: Premium Pen | G6: Stationery | H6: 1 | I6: 399 | J6: =H6*I6 | K6: UPI | L6: Online | M6: =TEXT(B6,"mmm-yyyy") | N6: =DATEDIF(B6,TODAY(),"d") | O6: =NOW()
A7: T0006 | B7: 46047 | C7: C004 | D7: Anaya Desai | E7: Central | F7: Water Bottle | G7: Lifestyle | H7: 4 | I7: 599 | J7: =H7*I7 | K7: Debit Card | L7: Online | M7: =TEXT(B7,"mmm-yyyy") | N7: =DATEDIF(B7,TODAY(),"d") | O7: =NOW()
A8: T0007 | B8: 46128 | C8: C018 | D8: Navya Desai | E8: East | F8: Keyboard | G8: Electronics | H8: 6 | I8: 1299 | J8: =H8*I8 | K8: UPI | L8: Mobile App | M8: =TEXT(B8,"mmm-yyyy") | N8: =DATEDIF(B8,TODAY(),"d") | O8: =NOW()
A9: T0008 | B9: 45958 | C9: C027 | D9: Ayaan Desai | E9: South | F9: Headphones | G9: Electronics | H9: 4 | I9: 2499 | J9: =H9*I9 | K9: Net Banking | L9: Online | M9: =TEXT(B9,"mmm-yyyy") | N9: =DATEDIF(B9,TODAY(),"d") | O9: =NOW()
A10: T0009 | B10: 45729 | C10: C002 | D10: Diya Shah | E10: West | F10: Notebook Pack | G10: Stationery | H10: 3 | I10: 249 | J10: =H10*I10 | K10: Credit Card | L10: Online | M10: =TEXT(B10,"mmm-yyyy") | N10: =DATEDIF(B10,TODAY(),"d") | O10: =NOW()
A11: T0010 | B11: 46047 | C11: C009 | D11: Aditya Patel | E11: South | F11: Desk Lamp | G11: Home | H11: 3 | I11: 1099 | J11: =H11*I11 | K11: Credit Card | L11: Store | M11: =TEXT(B11,"mmm-yyyy") | N11: =DATEDIF(B11,TODAY(),"d") | O11: =NOW()
A12: T0011 | B12: 46021 | C12: C007 | D12: Reyansh Modi | E12: West | F12: Premium Pen | G12: Stationery | H12: 3 | I12: 399 | J12: =H12*I12 | K12: Net Banking | L12: Mobile App | M12: =TEXT(B12,"mmm-yyyy") | N12: =DATEDIF(B12,TODAY(),"d") | O12: =NOW()
A13: T0012 | B13: 45833 | C13: C018 | D13: Navya Desai | E13: East | F13: Notebook Pack | G13: Stationery | H13: 1 | I13: 249 | J13: =H13*I13 | K13: Debit Card | L13: Mobile App | M13: =TEXT(B13,"mmm-yyyy") | N13: =DATEDIF(B13,TODAY(),"d") | O13: =NOW()
... A251: T0250 | B251: 45914 | C251: C002 | D251: Diya Shah | E251: Central | F251: Desk Lamp | G251: Home | H251: 4 | I251: 1099 | J251: =H251*I251 | K251: UPI | L251: Mobile App | M251: =TEXT(B251,"mmm-yyyy") | N251: =DATEDIF(B251,TODAY(),"d") | O251: =NOW()

Sheet Analysis
A1: Transaction Analysis & Formula Lab
A3: Metric | B3: Result | C3: Formula / explanation
A4: Total Revenue | B4: =SUM('Raw Data'!J2:J251) | C4: SUM of transaction revenue
A5: Total Transactions | B5: =COUNTA('Raw Data'!A2:A251) | C5: Count of transaction IDs
A6: Units Sold | B6: =SUM('Raw Data'!H2:H251) | C6: SUM of quantity
A7: Average Order Value | B7: =IFERROR(B4/B5,0) | C7: Total Revenue / Total Transactions
A8: Unique Customers | B8: =SUMPRODUCT(('Raw Data'!C2:C251<>"")/COUNTIF('Raw Data'!C2:C251,'Raw Data'!C2:C251&"")) | C8: Distinct customer IDs (array-compatible formula)
A9: Highest Transaction | B9: =MAX('Raw Data'!J2:J251) | C9: MAX revenue from one transaction
A10: Average Transaction | B10: =AVERAGE('Raw Data'!J2:J251) | C10: AVERAGE transaction revenue
A11: Current Date | B11: =TODAY() | C11: TODAY date function
A12: Current Date & Time | B12: =NOW() | C12: NOW date-time function
A13: End of Current Month | B13: =EOMONTH(TODAY(),0) | C13: EOMONTH current month end
A14: Sample Tenure Days | B14: =DATEDIF(MIN('Raw Data'!B2:B251),TODAY(),"d") | C14: DATEDIF from first transaction date to today
A16: Revenue by Region | E16: Revenue by Product
A17: Region | B17: Revenue | C17: Transactions | E17: Product | F17: Revenue | G17: Units Sold
A18: West | B18: =SUMIF('Raw Data'!$E$2:$E$251,A18,'Raw Data'!$J$2:$J$251) | C18: =COUNTIF('Raw Data'!$E$2:$E$251,A18) | E18: Wireless Mouse | F18: =SUMIF('Raw Data'!$F$2:$F$251,E18,'Raw Data'!$J$2:$J$251) | G18: =SUMIF('Raw Data'!$F$2:$F$251,E18,'Raw Data'!$H$2:$H$251)
A19: North | B19: =SUMIF('Raw Data'!$E$2:$E$251,A19,'Raw Data'!$J$2:$J$251) | C19: =COUNTIF('Raw Data'!$E$2:$E$251,A19) | E19: Keyboard | F19: =SUMIF('Raw Data'!$F$2:$F$251,E19,'Raw Data'!$J$2:$J$251) | G19: =SUMIF('Raw Data'!$F$2:$F$251,E19,'Raw Data'!$H$2:$H$251)
A20: South | B20: =SUMIF('Raw Data'!$E$2:$E$251,A20,'Raw Data'!$J$2:$J$251) | C20: =COUNTIF('Raw Data'!$E$2:$E$251,A20) | E20: USB-C Hub | F20: =SUMIF('Raw Data'!$F$2:$F$251,E20,'Raw Data'!$J$2:$J$251) | G20: =SUMIF('Raw Data'!$F$2:$F$251,E20,'Raw Data'!$H$2:$H$251)
A21: East | B21: =SUMIF('Raw Data'!$E$2:$E$251,A21,'Raw Data'!$J$2:$J$251) | C21: =COUNTIF('Raw Data'!$E$2:$E$251,A21) | E21: Notebook Pack | F21: =SUMIF('Raw Data'!$F$2:$F$251,E21,'Raw Data'!$J$2:$J$251) | G21: =SUMIF('Raw Data'!$F$2:$F$251,E21,'Raw Data'!$H$2:$H$251)
A22: Central | B22: =SUMIF('Raw Data'!$E$2:$E$251,A22,'Raw Data'!$J$2:$J$251) | C22: =COUNTIF('Raw Data'!$E$2:$E$251,A22) | E22: Premium Pen | F22: =SUMIF('Raw Data'!$F$2:$F$251,E22,'Raw Data'!$J$2:$J$251) | G22: =SUMIF('Raw Data'!$F$2:$F$251,E22,'Raw Data'!$H$2:$H$251)
E23: Water Bottle | F23: =SUMIF('Raw Data'!$F$2:$F$251,E23,'Raw Data'!$J$2:$J$251) | G23: =SUMIF('Raw Data'!$F$2:$F$251,E23,'Raw Data'!$H$2:$H$251)
E24: Backpack | F24: =SUMIF('Raw Data'!$F$2:$F$251,E24,'Raw Data'!$J$2:$J$251) | G24: =SUMIF('Raw Data'!$F$2:$F$251,E24,'Raw Data'!$H$2:$H$251)
E25: Desk Lamp | F25: =SUMIF('Raw Data'!$F$2:$F$251,E25,'Raw Data'!$J$2:$J$251) | G25: =SUMIF('Raw Data'!$F$2:$F$251,E25,'Raw Data'!$H$2:$H$251)
A26: Monthly Revenue Trend | E26: Coffee Mug | F26: =SUMIF('Raw Data'!$F$2:$F$251,E26,'Raw Data'!$J$2:$J$251) | G26: =SUMIF('Raw Data'!$F$2:$F$251,E26,'Raw Data'!$H$2:$H$251)
A27: Month | B27: Revenue | E27: Headphones | F27: =SUMIF('Raw Data'!$F$2:$F$251,E27,'Raw Data'!$J$2:$J$251) | G27: =SUMIF('Raw Data'!$F$2:$F$251,E27,'Raw Data'!$H$2:$H$251)
A28: 45658 | B28: =SUMIFS('Raw Data'!$J$2:$J$251,'Raw Data'!$B$2:$B$251,">="&A28,'Raw Data'!$B$2:$B$251,"<"&EOMONTH(A28,0)+1)
A29: 45689 | B29: =SUMIFS('Raw Data'!$J$2:$J$251,'Raw Data'!$B$2:$B$251,">="&A29,'Raw Data'!$B$2:$B$251,"<"&EOMONTH(A29,0)+1)
A30: 45717 | B30: =SUMIFS('Raw Data'!$J$2:$J$251,'Raw Data'!$B$2:$B$251,">="&A30,'Raw Data'!$B$2:$B$251,"<"&EOMONTH(A30,0)+1) | E30: FILTER example
A31: 45748 | B31: =SUMIFS('Raw Data'!$J$2:$J$251,'Raw Data'!$B$2:$B$251,">="&A31,'Raw Data'!$B$2:$B$251,"<"&EOMONTH(A31,0)+1) | E31: High-value transactions (Revenue ≥ ₹2,000)
A32: 45778 | B32: =SUMIFS('Raw Data'!$J$2:$J$251,'Raw Data'!$B$2:$B$251,">="&A32,'Raw Data'!$B$2:$B$251,"<"&EOMONTH(A32,0)+1) | E32: =FILTER('Raw Data'!A2:J251,'Raw Data'!J2:J251>=2000,"No matching transactions")
A33: 45809 | B33: =SUMIFS('Raw Data'!$J$2:$J$251,'Raw Data'!$B$2:$B$251,">="&A33,'Raw Data'!$B$2:$B$251,"<"&EOMONTH(A33,0)+1)
A34: 45839 | B34: =SUMIFS('Raw Data'!$J$2:$J$251,'Raw Data'!$B$2:$B$251,">="&A34,'Raw Data'!$B$2:$B$251,"<"&EOMONTH(A34,0)+1) | E34: Compatibility | F34: If FILTER is unavailable, apply the Revenue filter on Raw Data and select values ≥ 2000.
A35: 45870 | B35: =SUMIFS('Raw Data'!$J$2:$J$251,'Raw Data'!$B$2:$B$251,">="&A35,'Raw Data'!$B$2:$B$251,"<"&EOMONTH(A35,0)+1)
A36: 45901 | B36: =SUMIFS('Raw Data'!$J$2:$J$251,'Raw Data'!$B$2:$B$251,">="&A36,'Raw Data'!$B$2:$B$251,"<"&EOMONTH(A36,0)+1)
A37: 45931 | B37: =SUMIFS('Raw Data'!$J$2:$J$251,'Raw Data'!$B$2:$B$251,">="&A37,'Raw Data'!$B$2:$B$251,"<"&EOMONTH(A37,0)+1)
A38: 45962 | B38: =SUMIFS('Raw Data'!$J$2:$J$251,'Raw Data'!$B$2:$B$251,">="&A38,'Raw Data'!$B$2:$B$251,"<"&EOMONTH(A38,0)+1)
A39: 45992 | B39: =SUMIFS('Raw Data'!$J$2:$J$251,'Raw Data'!$B$2:$B$251,">="&A39,'Raw Data'!$B$2:$B$251,"<"&EOMONTH(A39,0)+1)
A40: 46023 | B40: =SUMIFS('Raw Data'!$J$2:$J$251,'Raw Data'!$B$2:$B$251,">="&A40,'Raw Data'!$B$2:$B$251,"<"&EOMONTH(A40,0)+1)
A41: 46054 | B41: =SUMIFS('Raw Data'!$J$2:$J$251,'Raw Data'!$B$2:$B$251,">="&A41,'Raw Data'!$B$2:$B$251,"<"&EOMONTH(A41,0)+1)
A42: 46082 | B42: =SUMIFS('Raw Data'!$J$2:$J$251,'Raw Data'!$B$2:$B$251,">="&A42,'Raw Data'!$B$2:$B$251,"<"&EOMONTH(A42,0)+1)
...

Sheet Visualizations
A1: Visualizations — Regional, Product & Monthly Performance

Sheet Dashboard
A1: DATA INTELLIGENCE DASHBOARD
A2: Customer Transaction Analysis | Sample dataset: 250 transactions
A4: Total Revenue | C4: Transactions | E4: Units Sold | G4: Average Order Value | I4: Unique Customers | K4: Highest Transaction
A5: =Analysis!B4 | C5: =Analysis!B5 | E5: =Analysis!B6 | G5: =Analysis!B7 | I5: =Analysis!B8 | K5: =Analysis!B9
A7: Dashboard guide
A8: Use the charts below to compare regional revenue, product contribution and monthly trend. Change source values on Raw Data to refresh formula-driven metrics.

Sheet Final Report
A1: Final Report — Insights & Business Storytelling
A3: Executive Summary
A4: This workbook analyzes 250 sample customer transactions across five regions and ten products. The dashboard summarizes revenue, transaction volume, units sold, average order value and customer reach. Replace the sample data with the instructor-provided dataset before submitting if one is available.
A8: Key questions answered
A9: 1. Which region contributes the most revenue? See Analysis regional summary and Dashboard bar chart.
A10: 2. Which products contribute the most revenue and volume? See Analysis product summary and product-share pie chart.
A11: 3. How does revenue change over time? See monthly revenue table and line chart.
A12: 4. Which customers and transactions may be high value? Filter Raw Data by revenue and use the FILTER example on Analysis.
A13: 5. What happens if revenue grows by a chosen percentage? Edit the growth assumption on What-If Analysis.
A14: 6. Is quantity associated with revenue? Review slope, intercept and R-squared on Regression.
A17: Recommendations
A18: • Prioritize inventory and campaigns for products with high revenue and consistent purchase volume.
... A26: Sample data is synthetic. NOW() and TODAY() are volatile formulas and update when Excel recalculates. The workbook uses formula-based summaries; native PivotTables, Slicers and Timelines should be added in desktop Excel if explicitly required.

Sheet What-If Analysis
A1: What-If Analysis — Scenario Manager & Goal Seek
A3: Input | B3: Value | C3: Notes
A4: Current Revenue | B4: =Analysis!B4 | C4: Linked to total revenue
A5: Expected Growth % | B5: 0.1 | C5: Edit growth assumption
A6: Projected Revenue | B6: =B4*(1+B5) | C6: Scenario result
A7: Target Revenue | B7: =B4*1.20 | C7: Example goal: 20% increase
A8: Required Growth % | B8: =IFERROR(B7/B4-1,0) | C8: Use Goal Seek to set B6 to B7 by changing B5
A11: Goal Seek instructions
A12: Data > What-If Analysis > Goal Seek: Set cell B6 to the target value in B7 by changing cell B5.
A15: Scenario Manager suggestion
A16: Create Low / Base / High scenarios by changing B5 to 5%, 10%, and 15%, then compare B6.

Sheet Regression
A1: Linear Regression — Quantity vs Revenue
A3: Model | B3: Value | C3: Interpretation
A4: Slope | B4: =SLOPE('Raw Data'!J2:J251,'Raw Data'!H2:H251) | C4: Estimated revenue change per additional unit (linear fit)
A5: Intercept | B5: =INTERCEPT('Raw Data'!J2:J251,'Raw Data'!H2:H251) | C5: Estimated baseline in the fitted model
A6: R-squared | B6: =RSQ('Raw Data'!J2:J251,'Raw Data'!H2:H251) | C6: Share of revenue variation explained by quantity in this simple model
A9: Data Analysis ToolPak
A10: In Excel: File > Options > Add-ins > Excel Add-ins > Go > check Analysis ToolPak. Then Data > Data Analysis > Regression. Y Range = J1:J251; X Range = H1:H251 (select Labels if headers included).
A14: Caution
A15: This is a simple illustrative model. Revenue also depends on product price and category, so do not interpret the relationship as causal.

Sheet Lists & Matching
A1: Repeated Values, List Matching & Text Abbreviations
A3: Product | B3: Purchase Count | C3: Most Purchased? | E3: Customer Name | F3: Abbreviation
A4: Wireless Mouse | B4: =COUNTIF('Raw Data'!$F$2:$F$251,A4) | C4: =IF(B4=MAX($B$4:$B$13),"TOP PRODUCT","") | E4: Aarav Patel | F4: =LEFT(E4,1)&"."&MID(E4,FIND(" ",E4)+1,1)&"."
A5: Keyboard | B5: =COUNTIF('Raw Data'!$F$2:$F$251,A5) | C5: =IF(B5=MAX($B$4:$B$13),"TOP PRODUCT","") | E5: Diya Shah | F5: =LEFT(E5,1)&"."&MID(E5,FIND(" ",E5)+1,1)&"."
A6: USB-C Hub | B6: =COUNTIF('Raw Data'!$F$2:$F$251,A6) | C6: =IF(B6=MAX($B$4:$B$13),"TOP PRODUCT","") | E6: Vivaan Mehta | F6: =LEFT(E6,1)&"."&MID(E6,FIND(" ",E6)+1,1)&"."
A7: Notebook Pack | B7: =COUNTIF('Raw Data'!$F$2:$F$251,A7) | C7: =IF(B7=MAX($B$4:$B$13),"TOP PRODUCT","") | E7: Anaya Desai | F7: =LEFT(E7,1)&"."&MID(E7,FIND(" ",E7)+1,1)&"."
A8: Premium Pen | B8: =COUNTIF('Raw Data'!$F$2:$F$251,A8) | C8: =IF(B8=MAX($B$4:$B$13),"TOP PRODUCT","") | E8: Arjun Joshi | F8: =LEFT(E8,1)&"."&MID(E8,FIND(" ",E8)+1,1)&"."
A9: Water Bottle | B9: =COUNTIF('Raw Data'!$F$2:$F$251,A9) | C9: =IF(B9=MAX($B$4:$B$13),"TOP PRODUCT","") | E9: Isha Trivedi | F9: =LEFT(E9,1)&"."&MID(E9,FIND(" ",E9)+1,1)&"."
A10: Backpack | B10: =COUNTIF('Raw Data'!$F$2:$F$251,A10) | C10: =IF(B10=MAX($B$4:$B$13),"TOP PRODUCT","") | E10: Reyansh Modi | F10: =LEFT(E10,1)&"."&MID(E10,FIND(" ",E10)+1,1)&"."
A11: Desk Lamp | B11: =COUNTIF('Raw Data'!$F$2:$F$251,A11) | C11: =IF(B11=MAX($B$4:$B$13),"TOP PRODUCT","") | E11: Myra Shah | F11: =LEFT(E11,1)&"."&MID(E11,FIND(" ",E11)+1,1)&"."
A12: Coffee Mug | B12: =COUNTIF('Raw Data'!$F$2:$F$251,A12) | C12: =IF(B12=MAX($B$4:$B$13),"TOP PRODUCT","") | E12: Aditya Patel | F12: =LEFT(E12,1)&"."&MID(E12,FIND(" ",E12)+1,1)&"."
A13: Headphones | B13: =COUNTIF('Raw Data'!$F$2:$F$251,A13) | C13: =IF(B13=MAX($B$4:$B$13),"TOP PRODUCT","") | E13: Sara Mehta | F13: =LEFT(E13,1)&"."&MID(E13,FIND(" ",E13)+1,1)&"."
E14: Krish Dave | F14: =LEFT(E14,1)&"."&MID(E14,FIND(" ",E14)+1,1)&"."
E15: Kiara Joshi | F15: =LEFT(E15,1)&"."&MID(E15,FIND(" ",E15)+1,1)&"."
A16: Compare two lists and extract matching names | E16: Rudra Desai | F16: =LEFT(E16,1)&"."&MID(E16,FIND(" ",E16)+1,1)&"."
A17: List A (Customer) | B17: List B (VIP list) | C17: Match in new column | E17: FILTER multi-value return | F17: =LEFT(E17,1)&"."&MID(E17,FIND(" ",E17)+1,1)&"."
A18: Aarav Patel | B18: Vivaan Mehta | C18: =IF(COUNTIF($B$18:$B$37,A18)>0,A18,"") | E18: =FILTER(A18:A37,C18:C37<>"","No matches") | F18: =LEFT(E18,1)&"."&MID(E18,FIND(" ",E18)+1,1)&"."
A19: Diya Shah | B19: Anaya Desai | C19: =IF(COUNTIF($B$18:$B$37,A19)>0,A19,"") | E19: Avni Patel | F19: =LEFT(E19,1)&"."&MID(E19,FIND(" ",E19)+1,1)&"."
A20: Vivaan Mehta | B20: Arjun Joshi | C20: =IF(COUNTIF($B$18:$B$37,A20)>0,A20,"") | E20: TEXT abbreviation example | F20: =LEFT(E20,1)&"."&MID(E20,FIND(" ",E20)+1,1)&"."
A21: Anaya Desai | B21: Isha Trivedi | C21: =IF(COUNTIF($B$18:$B$37,A21)>0,A21,"") | E21: =TEXT(TODAY(),"dd-mmm-yyyy") | F21: Date formatted as text
A22: Arjun Joshi | B22: Reyansh Modi | C22: =IF(COUNTIF($B$18:$B$37,A22)>0,A22,"") | E22: Dhruv Joshi | F22: =LEFT(E22,1)&"."&MID(E22,FIND(" ",E22)+1,1)&"."
A23: Isha Trivedi | B23: Myra Shah | C23: =IF(COUNTIF($B$18:$B$37,A23)>0,A23,"") | E23: Riya Modi | F23: =LEFT(E23,1)&"."&MID(E23,FIND(" ",E23)+1,1)&"."
A24: Reyansh Modi | B24: Aditya Patel | C24: =IF(COUNTIF($B$18:$B$37,A24)>0,A24,"") | E24: Manav Shah | F24: =LEFT(E24,1)&"."&MID(E24,FIND(" ",E24)+1,1)&"."
A25: Myra Shah | B25: Sara Mehta | C25: =IF(COUNTIF($B$18:$B$37,A25)>0,A25,"") | E25: Pari Patel | F25: =LEFT(E25,1)&"."&MID(E25,FIND(" ",E25)+1,1)&"."
A26: Aditya Patel | B26: Krish Dave | C26: =IF(COUNTIF($B$18:$B$37,A26)>0,A26,"") | E26: Yash Mehta | F26: =LEFT(E26,1)&"."&MID(E26,FIND(" ",E26)+1,1)&"."
A27: Sara Mehta | B27: Kiara Joshi | C27: =IF(COUNTIF($B$18:$B$37,A27)>0,A27,"") | E27: Saanvi Dave | F27: =LEFT(E27,1)&"."&MID(E27,FIND(" ",E27)+1,1)&"."
A28: Krish Dave | B28: Rohan Gandhi | C28: =IF(COUNTIF($B$18:$B$37,A28)>0,A28,"") | E28: Neil Trivedi | F28: =LEFT(E28,1)&"."&MID(E28,FIND(" ",E28)+1,1)&"."
A29: Kiara Joshi | B29: Meera Patel | C29: =IF(COUNTIF($B$18:$B$37,A29)>0,A29,"") | E29: Mira Joshi | F29: =LEFT(E29,1)&"."&MID(E29,FIND(" ",E29)+1,1)&"."
A30: Rudra Desai | B30: Vivaan Mehta | C30: =IF(COUNTIF($B$18:$B$37,A30)>0,A30,"") | E30: Ayaan Desai | F30: =LEFT(E30,1)&"."&MID(E30,FIND(" ",E30)+1,1)&"."
A31: Aanya Parmar | B31: Anaya Desai | C31: =IF(COUNTIF($B$18:$B$37,A31)>0,A31,"") | E31: Tara Shah | F31: =LEFT(E31,1)&"."&MID(E31,FIND(" ",E31)+1,1)&"."
A32: Dev Shah | B32: Arjun Joshi | C32: =IF(COUNTIF($B$18:$B$37,A32)>0,A32,"") | E32: Om Patel | F32: =LEFT(E32,1)&"."&MID(E32,FIND(" ",E32)+1,1)&"."
A33: Avni Patel | B33: Isha Trivedi | C33: =IF(COUNTIF($B$18:$B$37,A33)>0,A33,"") | E33: Zoya Mehta | F33: =LEFT(E33,1)&"."&MID(E33,FIND(" ",E33)+1,1)&"."
A34: Kabir Mehta | B34: Reyansh Modi | C34: =IF(COUNTIF($B$18:$B$37,A34)>0,A34,"")
A35: Navya Desai | B35: Myra Shah | C35: =IF(COUNTIF($B$18:$B$37,A35)>0,A35,"")
A36: Dhruv Joshi | B36: Aditya Patel | C36: =IF(COUNTIF($B$18:$B$37,A36)>0,A36,"")
A37: Riya Modi | B37: Sara Mehta | C37: =IF(COUNTIF($B$18:$B$37,A37)>0,A37,"")
